<?xml version="1.0" encoding="utf-8"?>
<!-- =================================================================================== -->
<!-- |    This document was autogenerated by xacro from /home/yifan/Dropbox/Vital_Sign_Monitoring/HATP_based/src/sophia_robot_description/urdf/description.xacro | -->
<!-- |    EDITING THIS FILE BY HAND IS NOT RECOMMENDED                                 | -->
<!-- =================================================================================== -->
<!-- 
To get urdf use:
rosrun xacro xacro.py `rospack find sophia_robot_description`/urdf/description.xacro > `rospack find sophia_robot_description`/urdf/sophia_robot.urdf
 -->
<robot name="sophia_robot">
  <!-- <xacro:include filename="/home/yifan/Dropbox/Vital_Sign_Monitoring/HATP_based/src/sophia_robot_description/urdf/sophia_right_hand_v3.urdf.xacro" />
	<xacro:include filename="/home/yifan/Dropbox/Vital_Sign_Monitoring/HATP_based/src/sophia_robot_description/urdf/sophia_left_hand_v3.urdf.xacro" /> -->
  <gazebo>
    <!-- <static>true</static> -->
    <plugin filename="libgazebo_ros_control.so" name="gazebo_ros_control">
      <!-- <robotNamespace>/sophia</robotNamespace> -->
      <legacyModeNS>true</legacyModeNS>
    </plugin>
  </gazebo>
  <gazebo reference="head_camera">
    <sensor name="head_sensor" type="camera">
      <update_rate>30.0</update_rate>
      <camera name="head_camera">
        <horizontal_fov>1.5</horizontal_fov>
        <image>
          <width>800</width>
          <height>600</height>
          <format>R8G8B8</format>
        </image>
        <clip>
          <near>0.02</near>
          <far>300</far>
        </clip>
        <noise>
          <type>gaussian</type>
          <!-- Noise is sampled independently per pixel on each frame.
					That pixel's noise value is added to each of its color
					channels, which at that point lie in the range [0,1]. -->
          <mean>0.0</mean>
          <stddev>0.007</stddev>
        </noise>
      </camera>
      <plugin filename="libgazebo_ros_camera.so" name="camera_controller">
        <alwaysOn>true</alwaysOn>
        <updateRate>0.0</updateRate>
        <cameraName>head/camera</cameraName>
        <imageTopicName>image_raw</imageTopicName>
        <cameraInfoTopicName>camera_info</cameraInfoTopicName>
        <frameName>head_camera</frameName>
        <hackBaseline>0.07</hackBaseline>
        <distortionK1>0.0</distortionK1>
        <distortionK2>0.0</distortionK2>
        <distortionK3>0.0</distortionK3>
        <distortionT1>0.0</distortionT1>
        <distortionT2>0.0</distortionT2>
      </plugin>
      <visualize>false</visualize>
    </sensor>
  </gazebo>
  <link name="base">
    <collision>
      <!-- Original ones seem off the place -->
      <!-- <origin xyz="0 0 0.075" rpy="0 0 0"/> -->
      <!-- Modified ones -->
      <origin rpy="0 0 0" xyz="0 0 0"/>
      <geometry>
        <mesh filename="package://sophia_robot_description/meshes/body/lower_torso.stl" scale="1 1 1"/>
      </geometry>
    </collision>
    <visual>
      <!-- Original ones seem off the place -->
      <!-- <origin xyz="0 0 0.075" rpy="0 0 0"/> -->
      <!-- Modified ones -->
      <origin rpy="0 0 0" xyz="0 0 0"/>
      <geometry>
        <mesh filename="package://sophia_robot_description/meshes/body/lower_torso.stl" scale="1 1 1"/>
      </geometry>
    </visual>
    <inertial>
      <origin rpy="0 0 0" xyz="0 0 0"/>
      <mass value="0.1"/>
      <inertia ixx="1e-3" ixy="0.0" ixz="0.0" iyy="1e-3" iyz="0.0" izz="1e-3"/>
    </inertial>
  </link>
  <link name="torso_yaw">
    <visual>
      <geometry>
        <mesh filename="package://sophia_robot_description/meshes/body/upper_torso.stl" scale="1 1 1"/>
      </geometry>
    </visual>
    <collision>
      <geometry>
        <mesh filename="package://sophia_robot_description/meshes/body/upper_torso.stl" scale="1 1 1"/>
      </geometry>
    </collision>
    <inertial>
      <mass value="0.1"/>
      <inertia ixx="1e-3" ixy="0.0" ixz="0.0" iyy="1e-3" iyz="0.0" izz="1e-3"/>
    </inertial>
  </link>
  <joint name="torso_yaw_joint" type="revolute">
    <parent link="base"/>
    <child link="torso_yaw"/>
    <!-- Original ones seem off the place -->
    <!-- <origin xyz="0 0 0.143" rpy="0 0 0"/> -->
    <!-- Modified ones -->
    <origin rpy="0 0 0" xyz="-0.03698509 -0.000917819 0.222723"/>
    <axis xyz="0 0 1"/>
    <limit effort="1000" lower="-2.9" upper="2.9" velocity="0.5"/>
  </joint>
  <link name="shoulder_center">
    <inertial>
      <mass value="0.1"/>
      <inertia ixx="1e-3" ixy="0.0" ixz="0.0" iyy="1e-3" iyz="0.0" izz="1e-3"/>
    </inertial>
  </link>
  <joint name="shoulder_center_joint" type="fixed">
    <parent link="torso_yaw"/>
    <child link="shoulder_center"/>
    <!-- Original ones seem off the place -->
    <!-- <origin xyz="-0.097 0 0.3182"/> -->
    <!-- Modified ones -->
    <origin xyz="-0.04794919 -0.001013606 0.1586865"/>
  </joint>
  <!--========================================== RIGHT PART ==================================================== -->
  <link name="right_shoulder_pitch">
    <inertial>
      <mass value="0.1"/>
      <inertia ixx="1e-3" ixy="0.0" ixz="0.0" iyy="1e-3" iyz="0.0" izz="1e-3"/>
    </inertial>
  </link>
  <joint name="right_shoulder_pitch_joint" type="revolute">
    <parent link="shoulder_center"/>
    <child link="right_shoulder_pitch"/>
    <origin rpy="0 0 0" xyz="0 -0.1728 0"/>
    <axis xyz="0 -0.99311 -0.11719"/>
    <limit effort="1000" lower="-0.489" upper="1.553" velocity="0.5"/>
    <!-- For testing -->
    <!-- <limit lower="-3.14159" upper="3.14159" effort="1000" velocity="0.5"/> -->
  </joint>
  <!-- Yifan note: available in unity rig -->
  <link name="right_shoulder_roll">
    <visual>
      <origin rpy="0 0 0"/>
      <geometry>
        <mesh filename="package://sophia_robot_description/meshes/body/right_upper_shoulder.stl" scale="1 1 1"/>
      </geometry>
    </visual>
    <collision>
      <origin rpy="0 0 0"/>
      <geometry>
        <mesh filename="package://sophia_robot_description/meshes/body/right_upper_shoulder.stl" scale="1 1 1"/>
      </geometry>
    </collision>
    <inertial>
      <mass value="0.1"/>
      <inertia ixx="1e-3" ixy="0.0" ixz="0.0" iyy="1e-3" iyz="0.0" izz="1e-3"/>
    </inertial>
  </link>
  <joint name="right_shoulder_roll_joint" type="revolute">
    <parent link="right_shoulder_pitch"/>
    <child link="right_shoulder_roll"/>
    <origin rpy="0 0 0" xyz="0 0 0"/>
    <axis xyz="1 0 0"/>
    <limit effort="1000" lower="-1.675" upper="0.017" velocity="0.5"/>
    <!-- For testing -->
    <!-- <limit lower="-3.14159" upper="3.14159" effort="1000" velocity="0.5"/> -->
  </joint>
  <!-- Yifan note: available in unity rig -->
  <link name="right_shoulder_yaw">
    <visual>
      <origin rpy="0 0 0"/>
      <geometry>
        <mesh filename="package://sophia_robot_description/meshes/body/right_lower_shoulder.stl" scale="1 1 1"/>
      </geometry>
    </visual>
    <collision>
      <origin rpy="0 0 0"/>
      <geometry>
        <mesh filename="package://sophia_robot_description/meshes/body/right_lower_shoulder.stl" scale="1 1 1"/>
      </geometry>
    </collision>
    <inertial>
      <mass value="0.1"/>
      <inertia ixx="1e-3" ixy="0.0" ixz="0.0" iyy="1e-3" iyz="0.0" izz="1e-3"/>
    </inertial>
  </link>
  <joint name="right_shoulder_yaw_joint" type="revolute">
    <parent link="right_shoulder_roll"/>
    <child link="right_shoulder_yaw"/>
    <origin rpy="0 0 0" xyz="0.0052 0 -0.1043"/>
    <axis xyz="0 0 -1"/>
    <limit effort="1000" lower="-1.169" upper="0.890" velocity="0.5"/>
    <!-- For testing -->
    <!-- <limit lower="-3.14159" upper="3.14159" effort="1000" velocity="0.5"/> -->
  </joint>
  <!-- Yifan note: place an artificial joint and link at the origin of right_elbow_yaw_joint
		for solving only. This joint has no further use. Although it is declared as revolute, it is treated as fixed,
		as it would always be set to 0 when solving for ik-->
  <link name="right_elbow_artificial">
    <inertial>
      <mass value="0.1"/>
      <inertia ixx="1e-3" ixy="0.0" ixz="0.0" iyy="1e-3" iyz="0.0" izz="1e-3"/>
    </inertial>
  </link>
  <joint name="right_elbow_artificial_joint" type="revolute">
    <parent link="right_elbow_pitch"/>
    <child link="right_elbow_artificial"/>
    <!-- Yifan note: origins directly computed from the elbow yaw,
			wrist pitch and wrist roll joint -->
    <origin rpy="0 0 0" xyz="0.0036 0 -0.235"/>
    <axis xyz="0 0 1"/>
    <limit effort="1000" lower="-3.14159" upper="3.14159" velocity="0.5"/>
  </joint>
  <!-- Yifan note: available in unity rig -->
  <link name="right_elbow_pitch">
    <visual>
      <origin rpy="0 0 0"/>
      <geometry>
        <mesh filename="package://sophia_robot_description/meshes/body/right_upper_lower_arm.stl" scale="1 1 1"/>
      </geometry>
    </visual>
    <collision>
      <origin rpy="0 0 0"/>
      <geometry>
        <mesh filename="package://sophia_robot_description/meshes/body/right_upper_lower_arm.stl" scale="1 1 1"/>
      </geometry>
    </collision>
    <inertial>
      <mass value="0.1"/>
      <inertia ixx="1e-3" ixy="0.0" ixz="0.0" iyy="1e-3" iyz="0.0" izz="1e-3"/>
    </inertial>
  </link>
  <joint name="right_elbow_pitch_joint" type="revolute">
    <parent link="right_shoulder_yaw"/>
    <child link="right_elbow_pitch"/>
    <origin rpy="0 0 0" xyz="-0.003 0 -0.1507"/>
    <axis xyz="0 1 0"/>
    <limit effort="1000" lower="-2.217" upper="0" velocity="0.5"/>
    <!-- For testing -->
    <!-- <limit lower="-3.14159" upper="3.14159" effort="1000" velocity="0.5"/> -->
  </joint>
  <!-- Yifan note: available in unity rig -->
  <link name="right_elbow_yaw">
    <visual>
      <origin rpy="0 0 0"/>
      <geometry>
        <mesh filename="package://sophia_robot_description/meshes/body/right_lower_lower_arm.stl" scale="1 1 1"/>
      </geometry>
    </visual>
    <collision>
      <origin rpy="0 0 0"/>
      <geometry>
        <mesh filename="package://sophia_robot_description/meshes/body/right_lower_lower_arm.stl" scale="1 1 1"/>
      </geometry>
    </collision>
    <inertial>
      <mass value="0.1"/>
      <inertia ixx="1e-3" ixy="0.0" ixz="0.0" iyy="1e-3" iyz="0.0" izz="1e-3"/>
    </inertial>
  </link>
  <joint name="right_elbow_yaw_joint" type="revolute">
    <parent link="right_elbow_pitch"/>
    <child link="right_elbow_yaw"/>
    <origin rpy="0 0 0" xyz="0.0036 0 -0.0935"/>
    <axis xyz="0 0 1"/>
    <limit effort="1000" lower="-2.757" upper="0.0" velocity="0.5"/>
    <!-- For testing -->
    <!-- <limit lower="-3.14159" upper="3.14159" effort="1000" velocity="0.5"/> -->
  </joint>
  <!-- Yifan note: available in unity rig -->
  <link name="right_wrist_pitch">
    <inertial>
      <mass value="0.1"/>
      <inertia ixx="1e-3" ixy="0.0" ixz="0.0" iyy="1e-3" iyz="0.0" izz="1e-3"/>
    </inertial>
  </link>
  <joint name="right_wrist_pitch_joint" type="revolute">
    <parent link="right_elbow_yaw"/>
    <child link="right_wrist_pitch"/>
    <origin rpy="0 0 0" xyz="0 0 -0.1365"/>
    <axis xyz="0 -1 0"/>
    <limit effort="1000" lower="-0.995" upper="0.733" velocity="0.5"/>
    <!-- For testing -->
    <!-- <limit lower="-3.14159" upper="3.14159" effort="1000" velocity="0.5"/> -->
  </joint>
  <!-- Yifan note: similar artificial treatment as with the upper arm -->
  <link name="right_wrist_roll_artificial">
    <inertial>
      <mass value="0.1"/>
      <inertia ixx="1e-3" ixy="0.0" ixz="0.0" iyy="1e-3" iyz="0.0" izz="1e-3"/>
    </inertial>
  </link>
  <joint name="right_wrist_roll_artificial_joint" type="revolute">
    <parent link="right_wrist_pitch"/>
    <child link="right_wrist_roll_artificial"/>
    <!-- By experiment, rotating around x-axis from the original wrist roll joint frame 
			by 195 degrees best aligns the z-axis with the index finger  -->
    <origin rpy="-1.3089969 0 0" xyz="0 0 -0.005"/>
    <axis xyz="1 0 0"/>
    <!-- This one is for openrave ikfast generation -->
    <limit effort="1000" lower="-0.419" upper="+0.471" velocity="0.5"/>
    <!-- This joint has no limit due to its artificial nature-->
    <!-- The limit would be checked when setting the real joint after applying a proper offset -->
    <!-- <limit lower="-3.14159" upper="3.14159" effort="1000" velocity="0.5"/> -->
  </joint>
  <link name="right_wrist_roll">
    <inertial>
      <mass value="0.1"/>
      <inertia ixx="1e-3" ixy="0.0" ixz="0.0" iyy="1e-3" iyz="0.0" izz="1e-3"/>
    </inertial>
  </link>
  <joint name="right_wrist_roll_joint" type="revolute">
    <parent link="right_wrist_pitch"/>
    <child link="right_wrist_roll"/>
    <origin rpy="0 0 0" xyz="0 0 -0.005"/>
    <axis xyz="1 0 0"/>
    <!-- This is the original range which looks wrong to me. We use the one for left wrist roll instead for now -->
    <!-- <limit lower="-0.419" upper="0.332" effort="1000" velocity="0.5"/> -->
    <!-- Range mimicing the left wrist roll -->
    <limit effort="1000" lower="-0.419" upper="+0.471" velocity="0.5"/>
    <!-- For testing -->
    <!-- <limit lower="-3.14159" upper="3.14159" effort="1000" velocity="0.5"/> -->
  </joint>
  <link name="right_hand">
    <visual>
      <origin rpy="0 0 0.0"/>
      <geometry>
        <mesh filename="package://sophia_robot_description/meshes/body/right_hand.stl" scale="1 1 1"/>
      </geometry>
    </visual>
    <collision>
      <origin rpy="0 0 0.0"/>
      <geometry>
        <mesh filename="package://sophia_robot_description/meshes/body/right_hand.stl" scale="1 1 1"/>
      </geometry>
    </collision>
    <inertial>
      <mass value="0.1"/>
      <inertia ixx="1e-3" ixy="0.0" ixz="0.0" iyy="1e-3" iyz="0.0" izz="1e-3"/>
    </inertial>
  </link>
  <joint name="right_hand_joint" type="fixed">
    <parent link="right_wrist_roll"/>
    <child link="right_hand"/>
    <origin rpy="0 0 0" xyz="0 0 0.0"/>
  </joint>
  <!--========================================== LEFT PART ==================================================== -->
  <link name="left_shoulder_pitch">
    <inertial>
      <mass value="0.1"/>
      <inertia ixx="1e-3" ixy="0.0" ixz="0.0" iyy="1e-3" iyz="0.0" izz="1e-3"/>
    </inertial>
  </link>
  <joint name="left_shoulder_pitch_joint" type="revolute">
    <parent link="shoulder_center"/>
    <child link="left_shoulder_pitch"/>
    <origin rpy="0 0 0" xyz="0 0.1728 0"/>
    <axis xyz="0 0.99311 0.11719"/>
    <limit effort="1000" lower="-1.553" upper="0.489" velocity="0.5"/>
    <!-- For testing -->
    <!-- <limit lower="-3.14159" upper="3.14159" effort="1000" velocity="0.5"/> -->
  </joint>
  <!-- Yifan note: available in unity rig -->
  <link name="left_shoulder_roll">
    <visual>
      <origin rpy="0 0 0"/>
      <geometry>
        <mesh filename="package://sophia_robot_description/meshes/body/left_upper_shoulder.stl" scale="1 1 1"/>
      </geometry>
    </visual>
    <collision>
      <origin rpy="0 0 0"/>
      <geometry>
        <mesh filename="package://sophia_robot_description/meshes/body/left_upper_shoulder.stl" scale="1 1 1"/>
      </geometry>
    </collision>
    <inertial>
      <mass value="0.1"/>
      <inertia ixx="1e-3" ixy="0.0" ixz="0.0" iyy="1e-3" iyz="0.0" izz="1e-3"/>
    </inertial>
  </link>
  <joint name="left_shoulder_roll_joint" type="revolute">
    <parent link="left_shoulder_pitch"/>
    <child link="left_shoulder_roll"/>
    <origin rpy="0 0 0" xyz="0 0 0"/>
    <axis xyz="1 0 0"/>
    <limit effort="1000" lower="-0.017" upper="1.884" velocity="0.5"/>
    <!-- For testing -->
    <!-- <limit lower="-3.14159" upper="3.14159" effort="1000" velocity="0.5"/> -->
  </joint>
  <!-- Yifan note: available in unity rig -->
  <link name="left_shoulder_yaw">
    <visual>
      <origin rpy="0 0 0"/>
      <geometry>
        <mesh filename="package://sophia_robot_description/meshes/body/left_lower_shoulder.stl" scale="1 1 1"/>
      </geometry>
    </visual>
    <collision>
      <origin rpy="0 0 0"/>
      <geometry>
        <mesh filename="package://sophia_robot_description/meshes/body/left_lower_shoulder.stl" scale="1 1 1"/>
      </geometry>
    </collision>
    <inertial>
      <mass value="0.1"/>
      <inertia ixx="1e-3" ixy="0.0" ixz="0.0" iyy="1e-3" iyz="0.0" izz="1e-3"/>
    </inertial>
  </link>
  <joint name="left_shoulder_yaw_joint" type="revolute">
    <parent link="left_shoulder_roll"/>
    <child link="left_shoulder_yaw"/>
    <origin rpy="0 0 0" xyz="0.0052 0 -0.1043"/>
    <axis xyz="0 0 -1"/>
    <limit effort="1000" lower="-0.977" upper="1.169" velocity="0.5"/>
    <!-- For testing -->
    <!-- <limit lower="-3.14159" upper="3.14159" effort="1000" velocity="0.5"/> -->
  </joint>
  <!-- Yifan note: same artificial treatment as the right case-->
  <link name="left_elbow_artificial">
    <inertial>
      <mass value="0.1"/>
      <inertia ixx="1e-3" ixy="0.0" ixz="0.0" iyy="1e-3" iyz="0.0" izz="1e-3"/>
    </inertial>
  </link>
  <joint name="left_elbow_artificial_joint" type="revolute">
    <parent link="left_elbow_pitch"/>
    <child link="left_elbow_artificial"/>
    <!-- Yifan note: origins directly computed from the elbow yaw,
			wrist pitch and wrist roll joint -->
    <origin rpy="0 0 0" xyz="0.0036 0 -0.235"/>
    <axis xyz="0 0 1"/>
    <limit effort="1000" lower="-3.14159" upper="3.14159" velocity="0.5"/>
  </joint>
  <!-- Yifan note: available in unity rig -->
  <link name="left_elbow_pitch">
    <visual>
      <origin rpy="0 0 0"/>
      <geometry>
        <mesh filename="package://sophia_robot_description/meshes/body/left_upper_lower_arm.stl" scale="1 1 1"/>
      </geometry>
    </visual>
    <collision>
      <origin rpy="0 0 0"/>
      <geometry>
        <mesh filename="package://sophia_robot_description/meshes/body/left_upper_lower_arm.stl" scale="1 1 1"/>
      </geometry>
    </collision>
    <inertial>
      <mass value="0.1"/>
      <inertia ixx="1e-3" ixy="0.0" ixz="0.0" iyy="1e-3" iyz="0.0" izz="1e-3"/>
    </inertial>
  </link>
  <joint name="left_elbow_pitch_joint" type="revolute">
    <parent link="left_shoulder_yaw"/>
    <child link="left_elbow_pitch"/>
    <origin rpy="0 0 0" xyz="-0.003 0 -0.1507"/>
    <axis xyz="0 -1 0"/>
    <limit effort="1000" lower="0" upper="2.270" velocity="0.5"/>
    <!-- For testing -->
    <!-- <limit lower="-3.14159" upper="3.14159" effort="1000" velocity="0.5"/> -->
  </joint>
  <!-- Yifan note: available in unity rig -->
  <link name="left_elbow_yaw">
    <visual>
      <origin rpy="0 0 0"/>
      <geometry>
        <mesh filename="package://sophia_robot_description/meshes/body/left_lower_lower_arm.stl" scale="1 1 1"/>
      </geometry>
    </visual>
    <collision>
      <origin rpy="0 0 0"/>
      <geometry>
        <mesh filename="package://sophia_robot_description/meshes/body/left_lower_lower_arm.stl" scale="1 1 1"/>
      </geometry>
    </collision>
    <inertial>
      <mass value="0.1"/>
      <inertia ixx="1e-3" ixy="0.0" ixz="0.0" iyy="1e-3" iyz="0.0" izz="1e-3"/>
    </inertial>
  </link>
  <joint name="left_elbow_yaw_joint" type="revolute">
    <parent link="left_elbow_pitch"/>
    <child link="left_elbow_yaw"/>
    <origin rpy="0 0 0" xyz="0.0036 0 -0.0935"/>
    <axis xyz="0 0 1"/>
    <limit effort="1000" lower="0" upper="2.946" velocity="0.5"/>
    <!-- For testing -->
    <!-- <limit lower="-3.14159" upper="3.14159" effort="1000" velocity="0.5"/> -->
  </joint>
  <!-- Yifan note: available in unity rig -->
  <link name="left_wrist_pitch">
    <inertial>
      <mass value="0.1"/>
      <inertia ixx="1e-3" ixy="0.0" ixz="0.0" iyy="1e-3" iyz="0.0" izz="1e-3"/>
    </inertial>
  </link>
  <joint name="left_wrist_pitch_joint" type="revolute">
    <parent link="left_elbow_yaw"/>
    <child link="left_wrist_pitch"/>
    <origin rpy="0 0 0" xyz="0 0 -0.1365"/>
    <axis xyz="0 1 0"/>
    <limit effort="1000" lower="-1.047" upper="+0.995" velocity="0.5"/>
    <!-- For testing -->
    <!-- <limit lower="-3.14159" upper="3.14159" effort="1000" velocity="0.5"/> -->
  </joint>
  <!-- Yifan note: same artificial treatment as the right case-->
  <link name="left_wrist_roll_artificial">
    <inertial>
      <mass value="0.1"/>
      <inertia ixx="1e-3" ixy="0.0" ixz="0.0" iyy="1e-3" iyz="0.0" izz="1e-3"/>
    </inertial>
  </link>
  <joint name="left_wrist_roll_artificial_joint" type="revolute">
    <parent link="left_wrist_pitch"/>
    <child link="left_wrist_roll_artificial"/>
    <origin rpy="-1.3089969 0 0" xyz="0 0 -0.005"/>
    <axis xyz="1 0 0"/>
    <!-- <limit lower="-0.471" upper="+0.419" effort="1000" velocity="0.5"/> -->
    <limit effort="1000" lower="-3.14159" upper="3.14159" velocity="0.5"/>
  </joint>
  <link name="left_wrist_roll">
    <inertial>
      <mass value="0.1"/>
      <inertia ixx="1e-3" ixy="0.0" ixz="0.0" iyy="1e-3" iyz="0.0" izz="1e-3"/>
    </inertial>
  </link>
  <joint name="left_wrist_roll_joint" type="revolute">
    <parent link="left_wrist_pitch"/>
    <child link="left_wrist_roll"/>
    <origin rpy="0 0 0" xyz="0 0 -0.005"/>
    <axis xyz="1 0 0"/>
    <limit effort="1000" lower="-0.471" upper="+0.419" velocity="0.5"/>
    <!-- For testing -->
    <!-- <limit lower="-3.14159" upper="3.14159" effort="1000" velocity="0.5"/> -->
  </joint>
  <link name="left_hand">
    <visual>
      <origin rpy="0 0 0.0"/>
      <geometry>
        <mesh filename="package://sophia_robot_description/meshes/body/left_hand.stl" scale="1 1 1"/>
      </geometry>
    </visual>
    <collision>
      <origin rpy="0 0 0.0"/>
      <geometry>
        <mesh filename="package://sophia_robot_description/meshes/body/left_hand.stl" scale="1 1 1"/>
      </geometry>
    </collision>
    <inertial>
      <mass value="0.1"/>
      <inertia ixx="1e-3" ixy="0.0" ixz="0.0" iyy="1e-3" iyz="0.0" izz="1e-3"/>
    </inertial>
  </link>
  <joint name="left_hand_joint" type="fixed">
    <parent link="left_wrist_roll"/>
    <child link="left_hand"/>
    <origin rpy="0 0 0" xyz="0 0 0.0"/>
  </joint>
</robot>

